Workbook

Sheet README
A1: Boundary OS × BSI × KPI — Spreadsheet v0.1 (Input/Output Spec + Prototype)
A3: Purpose
A4: Provide a minimal but functional workbook that ties together:
A5: • Five-layer scoring (L1–L5)
A6: • Boundary Stability Index (BSI) calculation
A7: • A simple Boundary State Machine (Normal → Tremor → Rupture → Repair)
A9: How to Use (Recommended)
A10: 1.Enter contextual information in columns C–H.
A11: 2.The prompt in column I will be generated automatically.
A12: 3.Copy the generated prompt and submit it to your preferred LLM.
A13: 4.Record returned scores in the BSI calculation sheet.
A14: 5.Review outputs alongside qualitative context and uncertainty.
... A34: [ DASHBOARD ]

Sheet Glossary
A1: 📘 Glossary Sheet — Initial Entries (Draft v0.4)
A3: Term | B3: Short Definition | C3: Extended Definition | D3: Layer / Scope | E3: Appears In | F3: Notes
A4: 🅐–🅑（Boundary OS / BSI Core）
A5: Boundary Operating System (Boundary OS) | B5: A socio-technical operating framework for managing dynamic boundaries in AI-mediated societies. | C5: Boundary OS is a conceptual and operational framework that treats social, institutional, and technological boundaries as dynamic, multi-layered systems rather than fixed lines. It integrates sensing, visualization, tuning, and repair functions across five layers (Material, Physio-Sensory, Affective, Narrative, Social/Institutional) while enforcing non-dominant AI mediation. The goal is not threat exclusion but responsive security through continuous boundary regulation. | D5: OS (L1–L5) | E5: Boundary OS paper, Appendix G, Spreadsheet | F5: Acts as the parent architecture for BSI and State Machine logic.
A6: Boundary Stability Index (BSI) | B6: A composite index measuring the stability and responsiveness of boundaries across five layers. | C6: BSI is a quantitative composite index designed to operationalize Boundary OS for policy evaluation. It aggregates normalized layer scores (L1–L5) using weighted summation to assess whether a system remains responsive under stress or approaches rupture. Unlike conventional risk indices, BSI explicitly incorporates affective and narrative layers, enabling early detection of socio-political instability before institutional breakdown. | D6: BSI (L1–L5) | E6: BSI paper, Appendix F.9, Spreadsheet | F6: Designed for simulation, comparison, and policy intervention modeling.
A7: 🅒–🅓（Conceptual Core）
A8: Boundary | B8: A functional interface regulating interaction, flow, and separation between systems. | C8: In Boundary OS, a boundary is not a wall but a regulatory membrane that modulates permeability, rigidity, and responsiveness. Boundaries exist across physical, biological, emotional, narrative, and institutional domains and are continuously reshaped by stress, interaction, and governance decisions. | D8: L1–L5 | E8: Boundary OS paper | F8: Key departure from territorial or legal-only boundary models.
A9: Boundary Tremor (Tremor) | B9: A detectable micro-instability indicating stress within a boundary. | C9: A tremor is a low-intensity, often pre-conscious signal of instability occurring before overt rupture. Tremors may manifest as physiological stress, emotional polarization, narrative drift, or minor institutional friction. Boundary OS prioritizes tremor detection to enable early tuning rather than post-collapse repair. | D9: L2–L4 | E9: Boundary OS, BSI | F9: Central to early-warning logic.
A10: Boundary Rupture | B10: A failure state where boundary regulation collapses. | C10: A rupture occurs when accumulated tremors exceed the system’s adaptive capacity, leading to loss of responsiveness (e.g., riots, policy deadlock, diplomatic breakdown). Boundary OS treats rupture as a recoverable state, provided repair mechanisms exist. | D10: L3–L5 | E10: Boundary OS, BSI | F10: Not synonymous with violence; includes narrative and institutional collapse.
A11: 🅔–🅖（Ethics & Governance）
A12: Breathing Membrane | B12: A boundary state that remains open, adaptive, and responsive under stress. | C12: The breathing membrane metaphor describes an optimal boundary condition where permeability and rigidity are continuously tuned rather than fixed. It rejects both total closure (securitization) and total openness (loss of sovereignty), enabling sustainable coexistence in plural societies. | D12: OS Concept | E12: Boundary OS paper | F12: Core normative image of the framework.
A13: Non-Dominant AI Mediation | B13: AI assists boundary perception but never replaces human judgment. | C13: Non-dominant AI mediation mandates that AI systems may detect, classify, visualize, and simulate boundary states, but may not judge, decide, or enforce normative outcomes. This principle preserves human agency and democratic accountability while leveraging AI’s sensing capacity. | D13: OS / Ethics | E13: Boundary OS, Appendix D, G | F13: Violation invalidates Boundary OS compliance.
A14: 🅗–🅚（KPI & Measurement）
A15: Key Performance Indicator (KPI) | B15: An operational metric used to evaluate system performance. | C15: In Boundary OS and BSI, KPIs are not endpoints but observational instruments. They measure responsiveness, recovery speed, narrative coherence, and trust levels rather than optimization targets. KPIs are explicitly subordinated to boundary health, avoiding Goodhart’s Law. | D15: KPI / BSI | E15: BSI paper, Appendix F, G | F15: KPIs inform tuning, not automated decisions.
A16: Interdependence Index | B16: A measure of cross-boundary reliance and coordination. | C16: This index quantifies the degree to which systems (states, institutions, communities) share data, narratives, and operational coordination. In BSI, higher interdependence correlates with resilience only when accompanied by narrative alignment and ethical safeguards. | D16: L4–L5 / KPI | E16: BSI paper | F16: High interdependence without trust increases fragility.
A17: 🅛–🅢（State Machine & System Logic）
A18: State Machine (Boundary State Machine) | B18: A formal model describing boundary transitions over time. | C18: The Boundary State Machine models how a system transitions between stable, stressed, ruptured, and repaired states based on BSI thresholds and policy interventions. It enables simulation of if–then scenarios without prescriptive automation. | D18: OS / BSI | E18: Boundary OS, BSI, Spreadsheet | F18: Analytical tool, not control logic.
A19: Repair | B19: Post-rupture reconnection of boundary functions. | C19: Repair refers to restoring boundary responsiveness after rupture through narrative reconciliation, institutional adjustment, and trust rebuilding. Repair prioritizes legitimacy over speed and may involve deliberate slowdown. | D19: L4–L5 | E19: Boundary OS | F19: Distinct from rollback or suppression.
A21: Term | B21: Short Definition | C21: Extended Definition | D21: Layer / Scope | E21: Appears In | F21: Notes | G21: Operational Meaning | H21: Measurement / Reference
A22: Affective Layer | B22: L3 | C22: The layer representing collective and individual emotional states such as anxiety, fear, trust, anger, and relief that influence decision-making and social dynamics. | D22: Layer 3 | E22: Boundary OS | F22: Often acts as a bridge between Physio-Sensory and Narrative layers. | G22: Used to detect emotional escalation preceding narrative or institutional rupture. | H22: Sentiment analysis, survey affect scores, media tone indices.
A23: AI Mediation (Non-dominant) | B23: AI-M | C23: A design principle in which AI systems function strictly as boundary media for sensing, visualization, and advisory support, without exercising judgment, authority, or enforcement. | D23: Cross-layer | E23: Boundary OS / Ethics | F23: Core ethical constraint of Boundary OS. | G23: AI may flag, simulate, or visualize but cannot decide or prescribe actions. | H23: Governance protocol compliance, override frequency.
A24: Boundary Operating System (Boundary OS) | B24: BOS | C24: A socio-technical framework for managing dynamic boundaries across material, physiological, affective, narrative, and institutional layers through sensing, tuning, and repair. | D24: Meta | E24: Boundary OS | F24: Provides the architecture connecting datasets, dashboards, and decision protocols. | G24: Provides the architecture connecting datasets, dashboards, and decision protocols. | H24: System-wide performance indicators, rupture frequency.
A25: Boundary Stability Index (BSI) | B25: BSI | C25: A composite index quantifying the stability of multi-layer boundaries by aggregating weighted layer scores. | D25: Cross-layer | E25: BSI | F25: Designed for comparative and longitudinal analysis. | G25: Primary output metric for policy monitoring and simulation. | H25: BSI=∑i=15wi⋅Li\text{BSI} = \sum_{i=1}^{5} w_i \cdot L_iBSI=∑i=15​wi​⋅Li​
A26: Breathing Membrane | B26: BM | C26: A metaphor describing boundaries as adaptive, permeable, and responsive systems rather than rigid walls or collapsed interfaces. | D26: Meta | E26: Boundary OS / Ethics | F26: Philosophical core of Responsive Security. | G26: Guides tuning decisions (do not seal, do not rupture). | H26: Variance tolerance thresholds, permeability indicators.
A27: Co-Subjectivity | B27: Co-Sub | C27: An ontological stance in which humans and non-human agents (including AI) participate in shared processes without collapsing into a single subject or hierarchy. | D27: Meta | E27: Ethics / Techno-Animism | F27: Distinguishes Boundary OS from instrumental AI models. | G27: Justifies AI as a participant medium, not a sovereign actor. | H27: Not directly quantified; reflected in governance design.
A28: Dynamic Ethical Boundary Lines | B28: DEBL | C28: A framework describing ethical boundaries as context-sensitive, temporally adaptive lines rather than fixed prohibitions. | D28: Meta | E28: Ethics / Method | F28: Ethical backbone for Boundary OS and BSI. | G28: Supports conditional rule-setting in AI governance. | H28: Ethical override logs, audit outcomes.
A29: Key Performance Indicator (KPI) | B29: KPI | C29: Quantitative or qualitative metrics used to evaluate system performance relative to predefined objectives. | D29: Cross-layer | E29: KPI | F29: KPIs are inputs to BSI, not substitutes for it. | G29: Used to validate Boundary OS interventions and BSI changes. | H29: Response time, trust scores, rupture frequency.
A30: Universal Plurality | B30: UP | C30: The principle that universality emerges from sustained coexistence of irreducible differences rather than homogenization. | D30: Meta | E30: Ethics / Techno-Animism | F30: Core normative principle of the project. | G30: Justifies multi-layer, non-unified metrics like BSI. | H30: Reflected indirectly through diversity and resilience indicators.

Sheet CASE_INPUT
A1: Case Input (raw indicators + optional layer scores)
A3: Enter cases row-by-row. You may either: (a) fill raw indicators, or (b) directly input Layer Scores L1–L5.
A5: Case_ID | B5: Date | C5: Region/Scope | D5: Scenario | E5: Notes | F5: Raw: Border arrivals (k) | G5: Raw: Housing pressure (0-100) | H5: Raw: Cyber incidents (count) | I5: Raw: Media negativity (0-100) | J5: Raw: Institutional backlog (days) | K5: Layer Score L1 (0-100) | L5: L2 (0-100) | M5: L3 (0-100) | N5: L4 (0-100) | O5: L5 (0-100)
A6: EU-2015 | B6: 42248 | C6: EU | D6: Migration crisis (synthetic) | E6: placeholder | F6: 1200 | G6: 78 | H6: 55 | I6: 72 | J6: 45
A7: EU-2023 | B7: 45200 | C7: EU | D7: Migration pressure (synthetic) | E7: placeholder | F7: 650 | G7: 62 | H7: 80 | I7: 68 | J7: 35
A8: SG-TRI-2026Q4 | B8: 46357 | C8: SG/TW/EE | D8: Tri-nation pilot baseline | E8: synthetic | F8: 12 | G8: 25 | H8: 15 | I8: 28 | J8: 10

Sheet Prompt_Generator
A1: 📄 Prompt Generation Sheet
A2: (Boundary OS × BSI | Spreadsheet v0.4)
A4: 🟦 Section 1: Context Input | L4: Prompt:Example
A6: Entry ID | B6: Date | C6: Context Type | D6: Geographic Scope | E6: Situation Description | F6: Observed Signals | G6: Affected Layers | H6: Policy Phase | I6: Prompt (Auto-generated) | J6: AI Output (Manual Paste) | L6: You are an analytical assistant tasked with quantifying social stability using the Boundary Stability Index (BSI). Context: - Policy domain: {{Context Type}} - Geographic scope: {{Geographic Scope}} - Policy phase: {{Policy Phase}} Situation description: {{Situation Description}} Observed signals: {{Observed Signals}} Task: 1. Assess the stability level of each Boundary OS layer (L1–L5). 2. Assign a normalized score (0–100) to each layer. 3. Briefly justify each score. 4. Indicate uncertainty or ambiguity if present. Important constraints: - Do not make policy recommendations. - Do not infer intent. - Focus on observable boundary stability only. Output format: L1 (Material): score / justification L2 (Physio-Sensory): score / justification L3 (Affective): score / justification L4 (Narrative): score / justification L5 (Social/Institutional): score / justification
A7: Unique ID for this case (e.g., EU-2015-01) | B7: YYYY-MM-DD | C7: Migration / Policing / Healthcare / Other | D7: EU-wide / National / Local | E7: Free text description (wrap text ON) | F7: List observable signals only. Examples: - protest frequency increased in urban areas - border processing delays reported - media reports of public anxiety - institutional capacity strain indicators Avoid interpretations or intent. | G7: Specify affected layers using L1–L5 notation. Example: L1, L3, L4 L1 = Material L2 = Physio-Sensory L3 = Affective L4 = Narrative L5 = Social/Institutional | H7: Pre-crisis / Crisis / Recovery | I7: copy | J7: paste
A8: 1 | B8: 46008 | C8: Migration | D8: EU-wide | E8: A sudden increase in irregular border crossings has been reported in multiple EU member states. | F8: protest frequency increased in urban areas | G8: L3 | H8: Pre-crisis | I8: ="You are an analytical assistant tasked with quantifying social stability using the Boundary Stability Index (BSI)."&CHAR(10)&CHAR(10)&"Context:"&CHAR(10)&"- Policy domain: "&C8&CHAR(10)&"- Geographic scope: "&D8&CHAR(10)&"- Policy phase: "&H8&CHAR(10)&"- Affected Layers: "&G8&CHAR(10)&CHAR(10)&"Situation description:"&CHAR(10)&E8&CHAR(10)&CHAR(10)&"Observed signals:"&CHAR(10)&F8&CHAR(10)&CHAR(10)&"Task:"&CHAR(10)&"1. Assess the stability level of each Boundary OS layer (L1–L5)."&CHAR(10)&"2. Assign a normalized score (0–100) to each layer."&CHAR(10)&"3. Briefly justify each score."&CHAR(10)&"4. Indicate uncertainty or ambiguity if present."&CHAR(10)&CHAR(10)&"Important constraints:"&CHAR(10)&"- Do not make policy recommendations."&CHAR(10)&"- Do not infer intent."&CHAR(10)&"- Focus on observable boundary stability only."&CHAR(10)&CHAR(10)&"Output format:"&CHAR(10)&"L1 (Material): score / justification"&CHAR(10)&"L2 (Physio-Sensory): score / justification"&CHAR(10)&"L3 (Affective): score / justification"&CHAR(10)&"L4 (Narrative): score / justification"&CHAR(10)&"L5 (Social/Institutional): score / justification" -> You are an analytical assistant tasked with quantifying social stability using the Boundary Stability Index (BSI). Context: - Policy domain: Migration - Geographic scope: EU-wide - Policy phase: Pre-crisis - Affected Layers: L3 Situation description: A sudden increase in irregular border crossings has been reported in multiple EU member states. Observed signals: protest frequency increased in urban areas Task: 1. Assess the stability level of each Boundary OS layer (L1–L5). 2. Assign a normalized score (0–100) to each layer. 3. Briefly justify each score. 4. Indicate uncertainty or ambiguity if present. Important constraints: - Do not make policy recommendations. - Do not infer intent. - Focus on observable boundary stability only. Output format: L1 (Material): score / justification L2 (Physio-Sensory): score / justification L3 (Affective): score / justification L4 (Narrative): score / justification L5 (Social/Institutional): score / justification | J8: L1 (Material): 65 / Justification Reports of a "sudden increase" in crossings imply immediate physical strain on border infrastructure and processing capacity. However, there is no signal of total physical breach or infrastructure collapse yet. L2 (Physio-Sensory): 75 / Justification While operational tempo has likely increased, causing potential fatigue among border personnel, there are no specific reports of violence, injury, or health emergencies (e.g., epidemic, starvation) at this stage. (Uncertainty: High, due to lack of specific biometric/medical data). L3 (Affective): 45 / Justification The observed signal "increased protest frequency" is a critical indicator of high collective anxiety and emotional volatility. This layer is currently the primary source of instability (Tremor) and requires immediate attention to prevent escalation. L4 (Narrative): 55 / Justification Public protests indicate a divergence in meaning-making and rising polarization regarding the migration event. The narrative boundary is under significant stress ("us vs. them" framing), though it has not yet fully ruptured into widespread chaotic conflict. L5 (Social/Institutional): 60 / Justification The situation involves "multiple member states," suggesting a strain on cross-border coordination mechanisms. While still in the "Pre-crisis" phase, the suddenness suggests institutions are reactive rather than proactive, likely leading to processing delays. | K8: ←for example | L8: 🔹 Example Entry
I9: ="You are an analytical assistant tasked with quantifying social stability using the Boundary Stability Index (BSI)."&CHAR(10)&CHAR(10)&"Context:"&CHAR(10)&"- Policy domain: "&C9&CHAR(10)&"- Geographic scope: "&D9&CHAR(10)&"- Policy phase: "&H9&CHAR(10)&"- Affected Layers: "&G9&CHAR(10)&CHAR(10)&"Situation description:"&CHAR(10)&E9&CHAR(10)&CHAR(10)&"Observed signals:"&CHAR(10)&F9&CHAR(10)&CHAR(10)&"Task:"&CHAR(10)&"1. Assess the stability level of each Boundary OS layer (L1–L5)."&CHAR(10)&"2. Assign a normalized score (0–100) to each layer."&CHAR(10)&"3. Briefly justify each score."&CHAR(10)&"4. Indicate uncertainty or ambiguity if present."&CHAR(10)&CHAR(10)&"Important constraints:"&CHAR(10)&"- Do not make policy recommendations."&CHAR(10)&"- Do not infer intent."&CHAR(10)&"- Focus on observable boundary stability only."&CHAR(10)&CHAR(10)&"Output format:"&CHAR(10)&"L1 (Material): score / justification"&CHAR(10)&"L2 (Physio-Sensory): score / justification"&CHAR(10)&"L3 (Affective): score / justification"&CHAR(10)&"L4 (Narrative): score / justification"&CHAR(10)&"L5 (Social/Institutional): score / justification" -> You are an analytical assistant tasked with quantifying social stability using the Boundary Stability Index (BSI). Context: - Policy domain: - Geographic scope: - Policy phase: - Affected Layers: Situation description: Observed signals: Task: 1. Assess the stability level of each Boundary OS layer (L1–L5). 2. Assign a normalized score (0–100) to each layer. 3. Briefly justify each score. 4. Indicate uncertainty or ambiguity if present. Important constraints: - Do not make policy recommendations. - Do not infer intent. - Focus on observable boundary stability only. Output format: L1 (Material): score / justification L2 (Physio-Sensory): score / justification L3 (Affective): score / justification L4 (Narrative): score / justification L5 (Social/Institutional): score / justification | L9: Context Type: Migration
I10: ="You are an analytical assistant tasked with quantifying social stability using the Boundary Stability Index (BSI)."&CHAR(10)&CHAR(10)&"Context:"&CHAR(10)&"- Policy domain: "&C10&CHAR(10)&"- Geographic scope: "&D10&CHAR(10)&"- Policy phase: "&H10&CHAR(10)&"- Affected Layers: "&G10&CHAR(10)&CHAR(10)&"Situation description:"&CHAR(10)&E10&CHAR(10)&CHAR(10)&"Observed signals:"&CHAR(10)&F10&CHAR(10)&CHAR(10)&"Task:"&CHAR(10)&"1. Assess the stability level of each Boundary OS layer (L1–L5)."&CHAR(10)&"2. Assign a normalized score (0–100) to each layer."&CHAR(10)&"3. Briefly justify each score."&CHAR(10)&"4. Indicate uncertainty or ambiguity if present."&CHAR(10)&CHAR(10)&"Important constraints:"&CHAR(10)&"- Do not make policy recommendations."&CHAR(10)&"- Do not infer intent."&CHAR(10)&"- Focus on observable boundary stability only."&CHAR(10)&CHAR(10)&"Output format:"&CHAR(10)&"L1 (Material): score / justification"&CHAR(10)&"L2 (Physio-Sensory): score / justification"&CHAR(10)&"L3 (Affective): score / justification"&CHAR(10)&"L4 (Narrative): score / justification"&CHAR(10)&"L5 (Social/Institutional): score / justification" -> You are an analytical assistant tasked with quantifying social stability using the Boundary Stability Index (BSI). Context: - Policy domain: - Geographic scope: - Policy phase: - Affected Layers: Situation description: Observed signals: Task: 1. Assess the stability level of each Boundary OS layer (L1–L5). 2. Assign a normalized score (0–100) to each layer. 3. Briefly justify each score. 4. Indicate uncertainty or ambiguity if present. Important constraints: - Do not make policy recommendations. - Do not infer intent. - Focus on observable boundary stability only. Output format: L1 (Material): score / justification L2 (Physio-Sensory): score / justification L3 (Affective): score / justification L4 (Narrative): score / justification L5 (Social/Institutional): score / justification | L10: Geographic Scope: EU-wide
I11: ="You are an analytical assistant tasked with quantifying social stability using the Boundary Stability Index (BSI)."&CHAR(10)&CHAR(10)&"Context:"&CHAR(10)&"- Policy domain: "&C11&CHAR(10)&"- Geographic scope: "&D11&CHAR(10)&"- Policy phase: "&H11&CHAR(10)&"- Affected Layers: "&G11&CHAR(10)&CHAR(10)&"Situation description:"&CHAR(10)&E11&CHAR(10)&CHAR(10)&"Observed signals:"&CHAR(10)&F11&CHAR(10)&CHAR(10)&"Task:"&CHAR(10)&"1. Assess the stability level of each Boundary OS layer (L1–L5)."&CHAR(10)&"2. Assign a normalized score (0–100) to each layer."&CHAR(10)&"3. Briefly justify each score."&CHAR(10)&"4. Indicate uncertainty or ambiguity if present."&CHAR(10)&CHAR(10)&"Important constraints:"&CHAR(10)&"- Do not make policy recommendations."&CHAR(10)&"- Do not infer intent."&CHAR(10)&"- Focus on observable boundary stability only."&CHAR(10)&CHAR(10)&"Output format:"&CHAR(10)&"L1 (Material): score / justification"&CHAR(10)&"L2 (Physio-Sensory): score / justification"&CHAR(10)&"L3 (Affective): score / justification"&CHAR(10)&"L4 (Narrative): score / justification"&CHAR(10)&"L5 (Social/Institutional): score / justification" -> You are an analytical assistant tasked with quantifying social stability using the Boundary Stability Index (BSI). Context: - Policy domain: - Geographic scope: - Policy phase: - Affected Layers: Situation description: Observed signals: Task: 1. Assess the stability level of each Boundary OS layer (L1–L5). 2. Assign a normalized score (0–100) to each layer. 3. Briefly justify each score. 4. Indicate uncertainty or ambiguity if present. Important constraints: - Do not make policy recommendations. - Do not infer intent. - Focus on observable boundary stability only. Output format: L1 (Material): score / justification L2 (Physio-Sensory): score / justification L3 (Affective): score / justification L4 (Narrative): score / justification L5 (Social/Institutional): score / justification | L11: Policy Phase: Crisis
I12: ="You are an analytical assistant tasked with quantifying social stability using the Boundary Stability Index (BSI)."&CHAR(10)&CHAR(10)&"Context:"&CHAR(10)&"- Policy domain: "&C12&CHAR(10)&"- Geographic scope: "&D12&CHAR(10)&"- Policy phase: "&H12&CHAR(10)&"- Affected Layers: "&G12&CHAR(10)&CHAR(10)&"Situation description:"&CHAR(10)&E12&CHAR(10)&CHAR(10)&"Observed signals:"&CHAR(10)&F12&CHAR(10)&CHAR(10)&"Task:"&CHAR(10)&"1. Assess the stability level of each Boundary OS layer (L1–L5)."&CHAR(10)&"2. Assign a normalized score (0–100) to each layer."&CHAR(10)&"3. Briefly justify each score."&CHAR(10)&"4. Indicate uncertainty or ambiguity if present."&CHAR(10)&CHAR(10)&"Important constraints:"&CHAR(10)&"- Do not make policy recommendations."&CHAR(10)&"- Do not infer intent."&CHAR(10)&"- Focus on observable boundary stability only."&CHAR(10)&CHAR(10)&"Output format:"&CHAR(10)&"L1 (Material): score / justification"&CHAR(10)&"L2 (Physio-Sensory): score / justification"&CHAR(10)&"L3 (Affective): score / justification"&CHAR(10)&"L4 (Narrative): score / justification"&CHAR(10)&"L5 (Social/Institutional): score / justification" -> You are an analytical assistant tasked with quantifying social stability using the Boundary Stability Index (BSI). Context: - Policy domain: - Geographic scope: - Policy phase: - Affected Layers: Situation description: Observed signals: Task: 1. Assess the stability level of each Boundary OS layer (L1–L5). 2. Assign a normalized score (0–100) to each layer. 3. Briefly justify each score. 4. Indicate uncertainty or ambiguity if present. Important constraints: - Do not make policy recommendations. - Do not infer intent. - Focus on observable boundary stability only. Output format: L1 (Material): score / justification L2 (Physio-Sensory): score / justification L3 (Affective): score / justification L4 (Narrative): score / justification L5 (Social/Institutional): score / justification | L12: Situation Description:
I13: ="You are an analytical assistant tasked with quantifying social stability using the Boundary Stability Index (BSI)."&CHAR(10)&CHAR(10)&"Context:"&CHAR(10)&"- Policy domain: "&C13&CHAR(10)&"- Geographic scope: "&D13&CHAR(10)&"- Policy phase: "&H13&CHAR(10)&"- Affected Layers: "&G13&CHAR(10)&CHAR(10)&"Situation description:"&CHAR(10)&E13&CHAR(10)&CHAR(10)&"Observed signals:"&CHAR(10)&F13&CHAR(10)&CHAR(10)&"Task:"&CHAR(10)&"1. Assess the stability level of each Boundary OS layer (L1–L5)."&CHAR(10)&"2. Assign a normalized score (0–100) to each layer."&CHAR(10)&"3. Briefly justify each score."&CHAR(10)&"4. Indicate uncertainty or ambiguity if present."&CHAR(10)&CHAR(10)&"Important constraints:"&CHAR(10)&"- Do not make policy recommendations."&CHAR(10)&"- Do not infer intent."&CHAR(10)&"- Focus on observable boundary stability only."&CHAR(10)&CHAR(10)&"Output format:"&CHAR(10)&"L1 (Material): score / justification"&CHAR(10)&"L2 (Physio-Sensory): score / justification"&CHAR(10)&"L3 (Affective): score / justification"&CHAR(10)&"L4 (Narrative): score / justification"&CHAR(10)&"L5 (Social/Institutional): score / justification" -> You are an analytical assistant tasked with quantifying social stability using the Boundary Stability Index (BSI). Context: - Policy domain: - Geographic scope: - Policy phase: - Affected Layers: Situation description: Observed signals: Task: 1. Assess the stability level of each Boundary OS layer (L1–L5). 2. Assign a normalized score (0–100) to each layer. 3. Briefly justify each score. 4. Indicate uncertainty or ambiguity if present. Important constraints: - Do not make policy recommendations. - Do not infer intent. - Focus on observable boundary stability only. Output format: L1 (Material): score / justification L2 (Physio-Sensory): score / justification L3 (Affective): score / justification L4 (Narrative): score / justification L5 (Social/Institutional): score / justification | L13: A sudden increase in irregular border crossings has been reported in multiple EU member states.
I14: ="You are an analytical assistant tasked with quantifying social stability using the Boundary Stability Index (BSI)."&CHAR(10)&CHAR(10)&"Context:"&CHAR(10)&"- Policy domain: "&C14&CHAR(10)&"- Geographic scope: "&D14&CHAR(10)&"- Policy phase: "&H14&CHAR(10)&"- Affected Layers: "&G14&CHAR(10)&CHAR(10)&"Situation description:"&CHAR(10)&E14&CHAR(10)&CHAR(10)&"Observed signals:"&CHAR(10)&F14&CHAR(10)&CHAR(10)&"Task:"&CHAR(10)&"1. Assess the stability level of each Boundary OS layer (L1–L5)."&CHAR(10)&"2. Assign a normalized score (0–100) to each layer."&CHAR(10)&"3. Briefly justify each score."&CHAR(10)&"4. Indicate uncertainty or ambiguity if present."&CHAR(10)&CHAR(10)&"Important constraints:"&CHAR(10)&"- Do not make policy recommendations."&CHAR(10)&"- Do not infer intent."&CHAR(10)&"- Focus on observable boundary stability only."&CHAR(10)&CHAR(10)&"Output format:"&CHAR(10)&"L1 (Material): score / justification"&CHAR(10)&"L2 (Physio-Sensory): score / justification"&CHAR(10)&"L3 (Affective): score / justification"&CHAR(10)&"L4 (Narrative): score / justification"&CHAR(10)&"L5 (Social/Institutional): score / justification" -> You are an analytical assistant tasked with quantifying social stability using the Boundary Stability Index (BSI). Context: - Policy domain: - Geographic scope: - Policy phase: - Affected Layers: Situation description: Observed signals: Task: 1. Assess the stability level of each Boundary OS layer (L1–L5). 2. Assign a normalized score (0–100) to each layer. 3. Briefly justify each score. 4. Indicate uncertainty or ambiguity if present. Important constraints: - Do not make policy recommendations. - Do not infer intent. - Focus on observable boundary stability only. Output format: L1 (Material): score / justification L2 (Physio-Sensory): score / justification L3 (Affective): score / justification L4 (Narrative): score / justification L5 (Social/Institutional): score / justification | L14: Public discourse shows heightened anxiety, while political actors issue conflicting statements.
I15: ="You are an analytical assistant tasked with quantifying social stability using the Boundary Stability Index (BSI)."&CHAR(10)&CHAR(10)&"Context:"&CHAR(10)&"- Policy domain: "&C15&CHAR(10)&"- Geographic scope: "&D15&CHAR(10)&"- Policy phase: "&H15&CHAR(10)&"- Affected Layers: "&G15&CHAR(10)&CHAR(10)&"Situation description:"&CHAR(10)&E15&CHAR(10)&CHAR(10)&"Observed signals:"&CHAR(10)&F15&CHAR(10)&CHAR(10)&"Task:"&CHAR(10)&"1. Assess the stability level of each Boundary OS layer (L1–L5)."&CHAR(10)&"2. Assign a normalized score (0–100) to each layer."&CHAR(10)&"3. Briefly justify each score."&CHAR(10)&"4. Indicate uncertainty or ambiguity if present."&CHAR(10)&CHAR(10)&"Important constraints:"&CHAR(10)&"- Do not make policy recommendations."&CHAR(10)&"- Do not infer intent."&CHAR(10)&"- Focus on observable boundary stability only."&CHAR(10)&CHAR(10)&"Output format:"&CHAR(10)&"L1 (Material): score / justification"&CHAR(10)&"L2 (Physio-Sensory): score / justification"&CHAR(10)&"L3 (Affective): score / justification"&CHAR(10)&"L4 (Narrative): score / justification"&CHAR(10)&"L5 (Social/Institutional): score / justification" -> You are an analytical assistant tasked with quantifying social stability using the Boundary Stability Index (BSI). Context: - Policy domain: - Geographic scope: - Policy phase: - Affected Layers: Situation description: Observed signals: Task: 1. Assess the stability level of each Boundary OS layer (L1–L5). 2. Assign a normalized score (0–100) to each layer. 3. Briefly justify each score. 4. Indicate uncertainty or ambiguity if present. Important constraints: - Do not make policy recommendations. - Do not infer intent. - Focus on observable boundary stability only. Output format: L1 (Material): score / justification L2 (Physio-Sensory): score / justification L3 (Affective): score / justification L4 (Narrative): score / justification L5 (Social/Institutional): score / justification | L15: Observed Signals:
I16: ="You are an analytical assistant tasked with quantifying social stability using the Boundary Stability Index (BSI)."&CHAR(10)&CHAR(10)&"Context:"&CHAR(10)&"- Policy domain: "&C16&CHAR(10)&"- Geographic scope: "&D16&CHAR(10)&"- Policy phase: "&H16&CHAR(10)&"- Affected Layers: "&G16&CHAR(10)&CHAR(10)&"Situation description:"&CHAR(10)&E16&CHAR(10)&CHAR(10)&"Observed signals:"&CHAR(10)&F16&CHAR(10)&CHAR(10)&"Task:"&CHAR(10)&"1. Assess the stability level of each Boundary OS layer (L1–L5)."&CHAR(10)&"2. Assign a normalized score (0–100) to each layer."&CHAR(10)&"3. Briefly justify each score."&CHAR(10)&"4. Indicate uncertainty or ambiguity if present."&CHAR(10)&CHAR(10)&"Important constraints:"&CHAR(10)&"- Do not make policy recommendations."&CHAR(10)&"- Do not infer intent."&CHAR(10)&"- Focus on observable boundary stability only."&CHAR(10)&CHAR(10)&"Output format:"&CHAR(10)&"L1 (Material): score / justification"&CHAR(10)&"L2 (Physio-Sensory): score / justification"&CHAR(10)&"L3 (Affective): score / justification"&CHAR(10)&"L4 (Narrative): score / justification"&CHAR(10)&"L5 (Social/Institutional): score / justification" -> You are an analytical assistant tasked with quantifying social stability using the Boundary Stability Index (BSI). Context: - Policy domain: - Geographic scope: - Policy phase: - Affected Layers: Situation description: Observed signals: Task: 1. Assess the stability level of each Boundary OS layer (L1–L5). 2. Assign a normalized score (0–100) to each layer. 3. Briefly justify each score. 4. Indicate uncertainty or ambiguity if present. Important constraints: - Do not make policy recommendations. - Do not infer intent. - Focus on observable boundary stability only. Output format: L1 (Material): score / justification L2 (Physio-Sensory): score / justification L3 (Affective): score / justification L4 (Narrative): score / justification L5 (Social/Institutional): score / justification | L16: Increase in border enforcement activity
I17: ="You are an analytical assistant tasked with quantifying social stability using the Boundary Stability Index (BSI)."&CHAR(10)&CHAR(10)&"Context:"&CHAR(10)&"- Policy domain: "&C17&CHAR(10)&"- Geographic scope: "&D17&CHAR(10)&"- Policy phase: "&H17&CHAR(10)&"- Affected Layers: "&G17&CHAR(10)&CHAR(10)&"Situation description:"&CHAR(10)&E17&CHAR(10)&CHAR(10)&"Observed signals:"&CHAR(10)&F17&CHAR(10)&CHAR(10)&"Task:"&CHAR(10)&"1. Assess the stability level of each Boundary OS layer (L1–L5)."&CHAR(10)&"2. Assign a normalized score (0–100) to each layer."&CHAR(10)&"3. Briefly justify each score."&CHAR(10)&"4. Indicate uncertainty or ambiguity if present."&CHAR(10)&CHAR(10)&"Important constraints:"&CHAR(10)&"- Do not make policy recommendations."&CHAR(10)&"- Do not infer intent."&CHAR(10)&"- Focus on observable boundary stability only."&CHAR(10)&CHAR(10)&"Output format:"&CHAR(10)&"L1 (Material): score / justification"&CHAR(10)&"L2 (Physio-Sensory): score / justification"&CHAR(10)&"L3 (Affective): score / justification"&CHAR(10)&"L4 (Narrative): score / justification"&CHAR(10)&"L5 (Social/Institutional): score / justification" -> You are an analytical assistant tasked with quantifying social stability using the Boundary Stability Index (BSI). Context: - Policy domain: - Geographic scope: - Policy phase: - Affected Layers: Situation description: Observed signals: Task: 1. Assess the stability level of each Boundary OS layer (L1–L5). 2. Assign a normalized score (0–100) to each layer. 3. Briefly justify each score. 4. Indicate uncertainty or ambiguity if present. Important constraints: - Do not make policy recommendations. - Do not infer intent. - Focus on observable boundary stability only. Output format: L1 (Material): score / justification L2 (Physio-Sensory): score / justification L3 (Affective): score / justification L4 (Narrative): score / justification L5 (Social/Institutional): score / justification | L17: Media framing migrants as security threat
I18: ="You are an analytical assistant tasked with quantifying social stability using the Boundary Stability Index (BSI)."&CHAR(10)&CHAR(10)&"Context:"&CHAR(10)&"- Policy domain: "&C18&CHAR(10)&"- Geographic scope: "&D18&CHAR(10)&"- Policy phase: "&H18&CHAR(10)&"- Affected Layers: "&G18&CHAR(10)&CHAR(10)&"Situation description:"&CHAR(10)&E18&CHAR(10)&CHAR(10)&"Observed signals:"&CHAR(10)&F18&CHAR(10)&CHAR(10)&"Task:"&CHAR(10)&"1. Assess the stability level of each Boundary OS layer (L1–L5)."&CHAR(10)&"2. Assign a normalized score (0–100) to each layer."&CHAR(10)&"3. Briefly justify each score."&CHAR(10)&"4. Indicate uncertainty or ambiguity if present."&CHAR(10)&CHAR(10)&"Important constraints:"&CHAR(10)&"- Do not make policy recommendations."&CHAR(10)&"- Do not infer intent."&CHAR(10)&"- Focus on observable boundary stability only."&CHAR(10)&CHAR(10)&"Output format:"&CHAR(10)&"L1 (Material): score / justification"&CHAR(10)&"L2 (Physio-Sensory): score / justification"&CHAR(10)&"L3 (Affective): score / justification"&CHAR(10)&"L4 (Narrative): score / justification"&CHAR(10)&"L5 (Social/Institutional): score / justification" -> You are an analytical assistant tasked with quantifying social stability using the Boundary Stability Index (BSI). Context: - Policy domain: - Geographic scope: - Policy phase: - Affected Layers: Situation description: Observed signals: Task: 1. Assess the stability level of each Boundary OS layer (L1–L5). 2. Assign a normalized score (0–100) to each layer. 3. Briefly justify each score. 4. Indicate uncertainty or ambiguity if present. Important constraints: - Do not make policy recommendations. - Do not infer intent. - Focus on observable boundary stability only. Output format: L1 (Material): score / justification L2 (Physio-Sensory): score / justification L3 (Affective): score / justification L4 (Narrative): score / justification L5 (Social/Institutional): score / justification | L18: Divergent national policy responses
I19: ="You are an analytical assistant tasked with quantifying social stability using the Boundary Stability Index (BSI)."&CHAR(10)&CHAR(10)&"Context:"&CHAR(10)&"- Policy domain: "&C19&CHAR(10)&"- Geographic scope: "&D19&CHAR(10)&"- Policy phase: "&H19&CHAR(10)&"- Affected Layers: "&G19&CHAR(10)&CHAR(10)&"Situation description:"&CHAR(10)&E19&CHAR(10)&CHAR(10)&"Observed signals:"&CHAR(10)&F19&CHAR(10)&CHAR(10)&"Task:"&CHAR(10)&"1. Assess the stability level of each Boundary OS layer (L1–L5)."&CHAR(10)&"2. Assign a normalized score (0–100) to each layer."&CHAR(10)&"3. Briefly justify each score."&CHAR(10)&"4. Indicate uncertainty or ambiguity if present."&CHAR(10)&CHAR(10)&"Important constraints:"&CHAR(10)&"- Do not make policy recommendations."&CHAR(10)&"- Do not infer intent."&CHAR(10)&"- Focus on observable boundary stability only."&CHAR(10)&CHAR(10)&"Output format:"&CHAR(10)&"L1 (Material): score / justification"&CHAR(10)&"L2 (Physio-Sensory): score / justification"&CHAR(10)&"L3 (Affective): score / justification"&CHAR(10)&"L4 (Narrative): score / justification"&CHAR(10)&"L5 (Social/Institutional): score / justification" -> You are an analytical assistant tasked with quantifying social stability using the Boundary Stability Index (BSI). Context: - Policy domain: - Geographic scope: - Policy phase: - Affected Layers: Situation description: Observed signals: Task: 1. Assess the stability level of each Boundary OS layer (L1–L5). 2. Assign a normalized score (0–100) to each layer. 3. Briefly justify each score. 4. Indicate uncertainty or ambiguity if present. Important constraints: - Do not make policy recommendations. - Do not infer intent. - Focus on observable boundary stability only. Output format: L1 (Material): score / justification L2 (Physio-Sensory): score / justification L3 (Affective): score / justification L4 (Narrative): score / justification L5 (Social/Institutional): score / justification
I20: ="You are an analytical assistant tasked with quantifying social stability using the Boundary Stability Index (BSI)."&CHAR(10)&CHAR(10)&"Context:"&CHAR(10)&"- Policy domain: "&C20&CHAR(10)&"- Geographic scope: "&D20&CHAR(10)&"- Policy phase: "&H20&CHAR(10)&"- Affected Layers: "&G20&CHAR(10)&CHAR(10)&"Situation description:"&CHAR(10)&E20&CHAR(10)&CHAR(10)&"Observed signals:"&CHAR(10)&F20&CHAR(10)&CHAR(10)&"Task:"&CHAR(10)&"1. Assess the stability level of each Boundary OS layer (L1–L5)."&CHAR(10)&"2. Assign a normalized score (0–100) to each layer."&CHAR(10)&"3. Briefly justify each score."&CHAR(10)&"4. Indicate uncertainty or ambiguity if present."&CHAR(10)&CHAR(10)&"Important constraints:"&CHAR(10)&"- Do not make policy recommendations."&CHAR(10)&"- Do not infer intent."&CHAR(10)&"- Focus on observable boundary stability only."&CHAR(10)&CHAR(10)&"Output format:"&CHAR(10)&"L1 (Material): score / justification"&CHAR(10)&"L2 (Physio-Sensory): score / justification"&CHAR(10)&"L3 (Affective): score / justification"&CHAR(10)&"L4 (Narrative): score / justification"&CHAR(10)&"L5 (Social/Institutional): score / justification" -> You are an analytical assistant tasked with quantifying social stability using the Boundary Stability Index (BSI). Context: - Policy domain: - Geographic scope: - Policy phase: - Affected Layers: Situation description: Observed signals: Task: 1. Assess the stability level of each Boundary OS layer (L1–L5). 2. Assign a normalized score (0–100) to each layer. 3. Briefly justify each score. 4. Indicate uncertainty or ambiguity if present. Important constraints: - Do not make policy recommendations. - Do not infer intent. - Focus on observable boundary stability only. Output format: L1 (Material): score / justification L2 (Physio-Sensory): score / justification L3 (Affective): score / justification L4 (Narrative): score / justification L5 (Social/Institutional): score / justification
I21: ="You are an analytical assistant tasked with quantifying social stability using the Boundary Stability Index (BSI)."&CHAR(10)&CHAR(10)&"Context:"&CHAR(10)&"- Policy domain: "&C21&CHAR(10)&"- Geographic scope: "&D21&CHAR(10)&"- Policy phase: "&H21&CHAR(10)&"- Affected Layers: "&G21&CHAR(10)&CHAR(10)&"Situation description:"&CHAR(10)&E21&CHAR(10)&CHAR(10)&"Observed signals:"&CHAR(10)&F21&CHAR(10)&CHAR(10)&"Task:"&CHAR(10)&"1. Assess the stability level of each Boundary OS layer (L1–L5)."&CHAR(10)&"2. Assign a normalized score (0–100) to each layer."&CHAR(10)&"3. Briefly justify each score."&CHAR(10)&"4. Indicate uncertainty or ambiguity if present."&CHAR(10)&CHAR(10)&"Important constraints:"&CHAR(10)&"- Do not make policy recommendations."&CHAR(10)&"- Do not infer intent."&CHAR(10)&"- Focus on observable boundary stability only."&CHAR(10)&CHAR(10)&"Output format:"&CHAR(10)&"L1 (Material): score / justification"&CHAR(10)&"L2 (Physio-Sensory): score / justification"&CHAR(10)&"L3 (Affective): score / justification"&CHAR(10)&"L4 (Narrative): score / justification"&CHAR(10)&"L5 (Social/Institutional): score / justification" -> You are an analytical assistant tasked with quantifying social stability using the Boundary Stability Index (BSI). Context: - Policy domain: - Geographic scope: - Policy phase: - Affected Layers: Situation description: Observed signals: Task: 1. Assess the stability level of each Boundary OS layer (L1–L5). 2. Assign a normalized score (0–100) to each layer. 3. Briefly justify each score. 4. Indicate uncertainty or ambiguity if present. Important constraints: - Do not make policy recommendations. - Do not infer intent. - Focus on observable boundary stability only. Output format: L1 (Material): score / justification L2 (Physio-Sensory): score / justification L3 (Affective): score / justification L4 (Narrative): score / justification L5 (Social/Institutional): score / justification
I22: ="You are an analytical assistant tasked with quantifying social stability using the Boundary Stability Index (BSI)."&CHAR(10)&CHAR(10)&"Context:"&CHAR(10)&"- Policy domain: "&C22&CHAR(10)&"- Geographic scope: "&D22&CHAR(10)&"- Policy phase: "&H22&CHAR(10)&"- Affected Layers: "&G22&CHAR(10)&CHAR(10)&"Situation description:"&CHAR(10)&E22&CHAR(10)&CHAR(10)&"Observed signals:"&CHAR(10)&F22&CHAR(10)&CHAR(10)&"Task:"&CHAR(10)&"1. Assess the stability level of each Boundary OS layer (L1–L5)."&CHAR(10)&"2. Assign a normalized score (0–100) to each layer."&CHAR(10)&"3. Briefly justify each score."&CHAR(10)&"4. Indicate uncertainty or ambiguity if present."&CHAR(10)&CHAR(10)&"Important constraints:"&CHAR(10)&"- Do not make policy recommendations."&CHAR(10)&"- Do not infer intent."&CHAR(10)&"- Focus on observable boundary stability only."&CHAR(10)&CHAR(10)&"Output format:"&CHAR(10)&"L1 (Material): score / justification"&CHAR(10)&"L2 (Physio-Sensory): score / justification"&CHAR(10)&"L3 (Affective): score / justification"&CHAR(10)&"L4 (Narrative): score / justification"&CHAR(10)&"L5 (Social/Institutional): score / justification" -> You are an analytical assistant tasked with quantifying social stability using the Boundary Stability Index (BSI). Context: - Policy domain: - Geographic scope: - Policy phase: - Affected Layers: Situation description: Observed signals: Task: 1. Assess the stability level of each Boundary OS layer (L1–L5). 2. Assign a normalized score (0–100) to each layer. 3. Briefly justify each score. 4. Indicate uncertainty or ambiguity if present. Important constraints: - Do not make policy recommendations. - Do not infer intent. - Focus on observable boundary stability only. Output format: L1 (Material): score / justification L2 (Physio-Sensory): score / justification L3 (Affective): score / justification L4 (Narrative): score / justification L5 (Social/Institutional): score / justification
I23: ="You are an analytical assistant tasked with quantifying social stability using the Boundary Stability Index (BSI)."&CHAR(10)&CHAR(10)&"Context:"&CHAR(10)&"- Policy domain: "&C23&CHAR(10)&"- Geographic scope: "&D23&CHAR(10)&"- Policy phase: "&H23&CHAR(10)&"- Affected Layers: "&G23&CHAR(10)&CHAR(10)&"Situation description:"&CHAR(10)&E23&CHAR(10)&CHAR(10)&"Observed signals:"&CHAR(10)&F23&CHAR(10)&CHAR(10)&"Task:"&CHAR(10)&"1. Assess the stability level of each Boundary OS layer (L1–L5)."&CHAR(10)&"2. Assign a normalized score (0–100) to each layer."&CHAR(10)&"3. Briefly justify each score."&CHAR(10)&"4. Indicate uncertainty or ambiguity if present."&CHAR(10)&CHAR(10)&"Important constraints:"&CHAR(10)&"- Do not make policy recommendations."&CHAR(10)&"- Do not infer intent."&CHAR(10)&"- Focus on observable boundary stability only."&CHAR(10)&CHAR(10)&"Output format:"&CHAR(10)&"L1 (Material): score / justification"&CHAR(10)&"L2 (Physio-Sensory): score / justification"&CHAR(10)&"L3 (Affective): score / justification"&CHAR(10)&"L4 (Narrative): score / justification"&CHAR(10)&"L5 (Social/Institutional): score / justification" -> You are an analytical assistant tasked with quantifying social stability using the Boundary Stability Index (BSI). Context: - Policy domain: - Geographic scope: - Policy phase: - Affected Layers: Situation description: Observed signals: Task: 1. Assess the stability level of each Boundary OS layer (L1–L5). 2. Assign a normalized score (0–100) to each layer. 3. Briefly justify each score. 4. Indicate uncertainty or ambiguity if present. Important constraints: - Do not make policy recommendations. - Do not infer intent. - Focus on observable boundary stability only. Output format: L1 (Material): score / justification L2 (Physio-Sensory): score / justification L3 (Affective): score / justification L4 (Narrative): score / justification L5 (Social/Institutional): score / justification
I24: ="You are an analytical assistant tasked with quantifying social stability using the Boundary Stability Index (BSI)."&CHAR(10)&CHAR(10)&"Context:"&CHAR(10)&"- Policy domain: "&C24&CHAR(10)&"- Geographic scope: "&D24&CHAR(10)&"- Policy phase: "&H24&CHAR(10)&"- Affected Layers: "&G24&CHAR(10)&CHAR(10)&"Situation description:"&CHAR(10)&E24&CHAR(10)&CHAR(10)&"Observed signals:"&CHAR(10)&F24&CHAR(10)&CHAR(10)&"Task:"&CHAR(10)&"1. Assess the stability level of each Boundary OS layer (L1–L5)."&CHAR(10)&"2. Assign a normalized score (0–100) to each layer."&CHAR(10)&"3. Briefly justify each score."&CHAR(10)&"4. Indicate uncertainty or ambiguity if present."&CHAR(10)&CHAR(10)&"Important constraints:"&CHAR(10)&"- Do not make policy recommendations."&CHAR(10)&"- Do not infer intent."&CHAR(10)&"- Focus on observable boundary stability only."&CHAR(10)&CHAR(10)&"Output format:"&CHAR(10)&"L1 (Material): score / justification"&CHAR(10)&"L2 (Physio-Sensory): score / justification"&CHAR(10)&"L3 (Affective): score / justification"&CHAR(10)&"L4 (Narrative): score / justification"&CHAR(10)&"L5 (Social/Institutional): score / justification" -> You are an analytical assistant tasked with quantifying social stability using the Boundary Stability Index (BSI). Context: - Policy domain: - Geographic scope: - Policy phase: - Affected Layers: Situation description: Observed signals: Task: 1. Assess the stability level of each Boundary OS layer (L1–L5). 2. Assign a normalized score (0–100) to each layer. 3. Briefly justify each score. 4. Indicate uncertainty or ambiguity if present. Important constraints: - Do not make policy recommendations. - Do not infer intent. - Focus on observable boundary stability only. Output format: L1 (Material): score / justification L2 (Physio-Sensory): score / justification L3 (Affective): score / justification L4 (Narrative): score / justification L5 (Social/Institutional): score / justification
I25: ="You are an analytical assistant tasked with quantifying social stability using the Boundary Stability Index (BSI)."&CHAR(10)&CHAR(10)&"Context:"&CHAR(10)&"- Policy domain: "&C25&CHAR(10)&"- Geographic scope: "&D25&CHAR(10)&"- Policy phase: "&H25&CHAR(10)&"- Affected Layers: "&G25&CHAR(10)&CHAR(10)&"Situation description:"&CHAR(10)&E25&CHAR(10)&CHAR(10)&"Observed signals:"&CHAR(10)&F25&CHAR(10)&CHAR(10)&"Task:"&CHAR(10)&"1. Assess the stability level of each Boundary OS layer (L1–L5)."&CHAR(10)&"2. Assign a normalized score (0–100) to each layer."&CHAR(10)&"3. Briefly justify each score."&CHAR(10)&"4. Indicate uncertainty or ambiguity if present."&CHAR(10)&CHAR(10)&"Important constraints:"&CHAR(10)&"- Do not make policy recommendations."&CHAR(10)&"- Do not infer intent."&CHAR(10)&"- Focus on observable boundary stability only."&CHAR(10)&CHAR(10)&"Output format:"&CHAR(10)&"L1 (Material): score / justification"&CHAR(10)&"L2 (Physio-Sensory): score / justification"&CHAR(10)&"L3 (Affective): score / justification"&CHAR(10)&"L4 (Narrative): score / justification"&CHAR(10)&"L5 (Social/Institutional): score / justification" -> You are an analytical assistant tasked with quantifying social stability using the Boundary Stability Index (BSI). Context: - Policy domain: - Geographic scope: - Policy phase: - Affected Layers: Situation description: Observed signals: Task: 1. Assess the stability level of each Boundary OS layer (L1–L5). 2. Assign a normalized score (0–100) to each layer. 3. Briefly justify each score. 4. Indicate uncertainty or ambiguity if present. Important constraints: - Do not make policy recommendations. - Do not infer intent. - Focus on observable boundary stability only. Output format: L1 (Material): score / justification L2 (Physio-Sensory): score / justification L3 (Affective): score / justification L4 (Narrative): score / justification L5 (Social/Institutional): score / justification
I26: ="You are an analytical assistant tasked with quantifying social stability using the Boundary Stability Index (BSI)."&CHAR(10)&CHAR(10)&"Context:"&CHAR(10)&"- Policy domain: "&C26&CHAR(10)&"- Geographic scope: "&D26&CHAR(10)&"- Policy phase: "&H26&CHAR(10)&"- Affected Layers: "&G26&CHAR(10)&CHAR(10)&"Situation description:"&CHAR(10)&E26&CHAR(10)&CHAR(10)&"Observed signals:"&CHAR(10)&F26&CHAR(10)&CHAR(10)&"Task:"&CHAR(10)&"1. Assess the stability level of each Boundary OS layer (L1–L5)."&CHAR(10)&"2. Assign a normalized score (0–100) to each layer."&CHAR(10)&"3. Briefly justify each score."&CHAR(10)&"4. Indicate uncertainty or ambiguity if present."&CHAR(10)&CHAR(10)&"Important constraints:"&CHAR(10)&"- Do not make policy recommendations."&CHAR(10)&"- Do not infer intent."&CHAR(10)&"- Focus on observable boundary stability only."&CHAR(10)&CHAR(10)&"Output format:"&CHAR(10)&"L1 (Material): score / justification"&CHAR(10)&"L2 (Physio-Sensory): score / justification"&CHAR(10)&"L3 (Affective): score / justification"&CHAR(10)&"L4 (Narrative): score / justification"&CHAR(10)&"L5 (Social/Institutional): score / justification" -> You are an analytical assistant tasked with quantifying social stability using the Boundary Stability Index (BSI). Context: - Policy domain: - Geographic scope: - Policy phase: - Affected Layers: Situation description: Observed signals: Task: 1. Assess the stability level of each Boundary OS layer (L1–L5). 2. Assign a normalized score (0–100) to each layer. 3. Briefly justify each score. 4. Indicate uncertainty or ambiguity if present. Important constraints: - Do not make policy recommendations. - Do not infer intent. - Focus on observable boundary stability only. Output format: L1 (Material): score / justification L2 (Physio-Sensory): score / justification L3 (Affective): score / justification L4 (Narrative): score / justification L5 (Social/Institutional): score / justification

Sheet LAYER_SCORES
A1: Layer Scores (computed if blank; otherwise pass-through from CASE_INPUT)
A4: Case_ID | B4: Date | C4: Region/Scope | D4: Scenario | E4: L1 | F4: L2 | G4: L3 | H4: L4 | I4: L5 | J4: Rule notes
A5: =CASE_INPUT!A6 -> EU-2015 | B5: =CASE_INPUT!B6 -> 42248 | C5: =CASE_INPUT!C6 -> EU | D5: =CASE_INPUT!D6 -> Migration crisis (synthetic) | E5: =IF(CASE_INPUT!K6<>"",CASE_INPUT!K6,MAX(0,100-MIN(100,CASE_INPUT!F6/20))) -> 40 | F5: =IF(CASE_INPUT!L6<>"",CASE_INPUT!L6,MAX(0,100-MIN(100,CASE_INPUT!H6*1.2))) -> 34 | G5: =IF(CASE_INPUT!M6<>"",CASE_INPUT!M6,MAX(0,100-CASE_INPUT!G6)) -> 22 | H5: =IF(CASE_INPUT!N6<>"",CASE_INPUT!N6,MAX(0,100-CASE_INPUT!I6)) -> 28 | I5: =IF(CASE_INPUT!O6<>"",CASE_INPUT!O6,MAX(0,100-MIN(100,CASE_INPUT!J6*1.5))) -> 32.5 | J5: v0.1 heuristics; replace with calibrated models
A6: =CASE_INPUT!A7 -> EU-2023 | B6: =CASE_INPUT!B7 -> 45200 | C6: =CASE_INPUT!C7 -> EU | D6: =CASE_INPUT!D7 -> Migration pressure (synthetic) | E6: =IF(CASE_INPUT!K7<>"",CASE_INPUT!K7,MAX(0,100-MIN(100,CASE_INPUT!F7/20))) -> 67.5 | F6: =IF(CASE_INPUT!L7<>"",CASE_INPUT!L7,MAX(0,100-MIN(100,CASE_INPUT!H7*1.2))) -> 4 | G6: =IF(CASE_INPUT!M7<>"",CASE_INPUT!M7,MAX(0,100-CASE_INPUT!G7)) -> 38 | H6: =IF(CASE_INPUT!N7<>"",CASE_INPUT!N7,MAX(0,100-CASE_INPUT!I7)) -> 32 | I6: =IF(CASE_INPUT!O7<>"",CASE_INPUT!O7,MAX(0,100-MIN(100,CASE_INPUT!J7*1.5))) -> 47.5 | J6: v0.1 heuristics; replace with calibrated models
A7: =CASE_INPUT!A8 -> SG-TRI-2026Q4 | B7: =CASE_INPUT!B8 -> 46357 | C7: =CASE_INPUT!C8 -> SG/TW/EE | D7: =CASE_INPUT!D8 -> Tri-nation pilot baseline | E7: =IF(CASE_INPUT!K8<>"",CASE_INPUT!K8,MAX(0,100-MIN(100,CASE_INPUT!F8/20))) -> 99.4 | F7: =IF(CASE_INPUT!L8<>"",CASE_INPUT!L8,MAX(0,100-MIN(100,CASE_INPUT!H8*1.2))) -> 82 | G7: =IF(CASE_INPUT!M8<>"",CASE_INPUT!M8,MAX(0,100-CASE_INPUT!G8)) -> 75 | H7: =IF(CASE_INPUT!N8<>"",CASE_INPUT!N8,MAX(0,100-CASE_INPUT!I8)) -> 72 | I7: =IF(CASE_INPUT!O8<>"",CASE_INPUT!O8,MAX(0,100-MIN(100,CASE_INPUT!J8*1.5))) -> 85 | J7: v0.1 heuristics; replace with calibrated models
A8: =CASE_INPUT!A9 | B8: =CASE_INPUT!B9 | C8: =CASE_INPUT!C9 | D8: =CASE_INPUT!D9 | E8: =IF(CASE_INPUT!K9<>"",CASE_INPUT!K9,MAX(0,100-MIN(100,CASE_INPUT!F9/20))) -> 100 | F8: =IF(CASE_INPUT!L9<>"",CASE_INPUT!L9,MAX(0,100-MIN(100,CASE_INPUT!H9*1.2))) -> 100 | G8: =IF(CASE_INPUT!M9<>"",CASE_INPUT!M9,MAX(0,100-CASE_INPUT!G9)) -> 100 | H8: =IF(CASE_INPUT!N9<>"",CASE_INPUT!N9,MAX(0,100-CASE_INPUT!I9)) -> 100 | I8: =IF(CASE_INPUT!O9<>"",CASE_INPUT!O9,MAX(0,100-MIN(100,CASE_INPUT!J9*1.5))) -> 100 | J8: v0.1 heuristics; replace with calibrated models
A9: =CASE_INPUT!A10 | B9: =CASE_INPUT!B10 | C9: =CASE_INPUT!C10 | D9: =CASE_INPUT!D10 | E9: =IF(CASE_INPUT!K10<>"",CASE_INPUT!K10,MAX(0,100-MIN(100,CASE_INPUT!F10/20))) -> 100 | F9: =IF(CASE_INPUT!L10<>"",CASE_INPUT!L10,MAX(0,100-MIN(100,CASE_INPUT!H10*1.2))) -> 100 | G9: =IF(CASE_INPUT!M10<>"",CASE_INPUT!M10,MAX(0,100-CASE_INPUT!G10)) -> 100 | H9: =IF(CASE_INPUT!N10<>"",CASE_INPUT!N10,MAX(0,100-CASE_INPUT!I10)) -> 100 | I9: =IF(CASE_INPUT!O10<>"",CASE_INPUT!O10,MAX(0,100-MIN(100,CASE_INPUT!J10*1.5))) -> 100 | J9: v0.1 heuristics; replace with calibrated models
A10: =CASE_INPUT!A11 | B10: =CASE_INPUT!B11 | C10: =CASE_INPUT!C11 | D10: =CASE_INPUT!D11 | E10: =IF(CASE_INPUT!K11<>"",CASE_INPUT!K11,MAX(0,100-MIN(100,CASE_INPUT!F11/20))) -> 100 | F10: =IF(CASE_INPUT!L11<>"",CASE_INPUT!L11,MAX(0,100-MIN(100,CASE_INPUT!H11*1.2))) -> 100 | G10: =IF(CASE_INPUT!M11<>"",CASE_INPUT!M11,MAX(0,100-CASE_INPUT!G11)) -> 100 | H10: =IF(CASE_INPUT!N11<>"",CASE_INPUT!N11,MAX(0,100-CASE_INPUT!I11)) -> 100 | I10: =IF(CASE_INPUT!O11<>"",CASE_INPUT!O11,MAX(0,100-MIN(100,CASE_INPUT!J11*1.5))) -> 100 | J10: v0.1 heuristics; replace with calibrated models
A11: =CASE_INPUT!A12 | B11: =CASE_INPUT!B12 | C11: =CASE_INPUT!C12 | D11: =CASE_INPUT!D12 | E11: =IF(CASE_INPUT!K12<>"",CASE_INPUT!K12,MAX(0,100-MIN(100,CASE_INPUT!F12/20))) -> 100 | F11: =IF(CASE_INPUT!L12<>"",CASE_INPUT!L12,MAX(0,100-MIN(100,CASE_INPUT!H12*1.2))) -> 100 | G11: =IF(CASE_INPUT!M12<>"",CASE_INPUT!M12,MAX(0,100-CASE_INPUT!G12)) -> 100 | H11: =IF(CASE_INPUT!N12<>"",CASE_INPUT!N12,MAX(0,100-CASE_INPUT!I12)) -> 100 | I11: =IF(CASE_INPUT!O12<>"",CASE_INPUT!O12,MAX(0,100-MIN(100,CASE_INPUT!J12*1.5))) -> 100 | J11: v0.1 heuristics; replace with calibrated models
A12: =CASE_INPUT!A13 | B12: =CASE_INPUT!B13 | C12: =CASE_INPUT!C13 | D12: =CASE_INPUT!D13 | E12: =IF(CASE_INPUT!K13<>"",CASE_INPUT!K13,MAX(0,100-MIN(100,CASE_INPUT!F13/20))) -> 100 | F12: =IF(CASE_INPUT!L13<>"",CASE_INPUT!L13,MAX(0,100-MIN(100,CASE_INPUT!H13*1.2))) -> 100 | G12: =IF(CASE_INPUT!M13<>"",CASE_INPUT!M13,MAX(0,100-CASE_INPUT!G13)) -> 100 | H12: =IF(CASE_INPUT!N13<>"",CASE_INPUT!N13,MAX(0,100-CASE_INPUT!I13)) -> 100 | I12: =IF(CASE_INPUT!O13<>"",CASE_INPUT!O13,MAX(0,100-MIN(100,CASE_INPUT!J13*1.5))) -> 100 | J12: v0.1 heuristics; replace with calibrated models
A13: =CASE_INPUT!A14 | B13: =CASE_INPUT!B14 | C13: =CASE_INPUT!C14 | D13: =CASE_INPUT!D14 | E13: =IF(CASE_INPUT!K14<>"",CASE_INPUT!K14,MAX(0,100-MIN(100,CASE_INPUT!F14/20))) -> 100 | F13: =IF(CASE_INPUT!L14<>"",CASE_INPUT!L14,MAX(0,100-MIN(100,CASE_INPUT!H14*1.2))) -> 100 | G13: =IF(CASE_INPUT!M14<>"",CASE_INPUT!M14,MAX(0,100-CASE_INPUT!G14)) -> 100 | H13: =IF(CASE_INPUT!N14<>"",CASE_INPUT!N14,MAX(0,100-CASE_INPUT!I14)) -> 100 | I13: =IF(CASE_INPUT!O14<>"",CASE_INPUT!O14,MAX(0,100-MIN(100,CASE_INPUT!J14*1.5))) -> 100 | J13: v0.1 heuristics; replace with calibrated models
A14: =CASE_INPUT!A15 | B14: =CASE_INPUT!B15 | C14: =CASE_INPUT!C15 | D14: =CASE_INPUT!D15 | E14: =IF(CASE_INPUT!K15<>"",CASE_INPUT!K15,MAX(0,100-MIN(100,CASE_INPUT!F15/20))) -> 100 | F14: =IF(CASE_INPUT!L15<>"",CASE_INPUT!L15,MAX(0,100-MIN(100,CASE_INPUT!H15*1.2))) -> 100 | G14: =IF(CASE_INPUT!M15<>"",CASE_INPUT!M15,MAX(0,100-CASE_INPUT!G15)) -> 100 | H14: =IF(CASE_INPUT!N15<>"",CASE_INPUT!N15,MAX(0,100-CASE_INPUT!I15)) -> 100 | I14: =IF(CASE_INPUT!O15<>"",CASE_INPUT!O15,MAX(0,100-MIN(100,CASE_INPUT!J15*1.5))) -> 100 | J14: v0.1 heuristics; replace with calibrated models
A15: =CASE_INPUT!A16 | B15: =CASE_INPUT!B16 | C15: =CASE_INPUT!C16 | D15: =CASE_INPUT!D16 | E15: =IF(CASE_INPUT!K16<>"",CASE_INPUT!K16,MAX(0,100-MIN(100,CASE_INPUT!F16/20))) -> 100 | F15: =IF(CASE_INPUT!L16<>"",CASE_INPUT!L16,MAX(0,100-MIN(100,CASE_INPUT!H16*1.2))) -> 100 | G15: =IF(CASE_INPUT!M16<>"",CASE_INPUT!M16,MAX(0,100-CASE_INPUT!G16)) -> 100 | H15: =IF(CASE_INPUT!N16<>"",CASE_INPUT!N16,MAX(0,100-CASE_INPUT!I16)) -> 100 | I15: =IF(CASE_INPUT!O16<>"",CASE_INPUT!O16,MAX(0,100-MIN(100,CASE_INPUT!J16*1.5))) -> 100 | J15: v0.1 heuristics; replace with calibrated models
A16: =CASE_INPUT!A17 | B16: =CASE_INPUT!B17 | C16: =CASE_INPUT!C17 | D16: =CASE_INPUT!D17 | E16: =IF(CASE_INPUT!K17<>"",CASE_INPUT!K17,MAX(0,100-MIN(100,CASE_INPUT!F17/20))) -> 100 | F16: =IF(CASE_INPUT!L17<>"",CASE_INPUT!L17,MAX(0,100-MIN(100,CASE_INPUT!H17*1.2))) -> 100 | G16: =IF(CASE_INPUT!M17<>"",CASE_INPUT!M17,MAX(0,100-CASE_INPUT!G17)) -> 100 | H16: =IF(CASE_INPUT!N17<>"",CASE_INPUT!N17,MAX(0,100-CASE_INPUT!I17)) -> 100 | I16: =IF(CASE_INPUT!O17<>"",CASE_INPUT!O17,MAX(0,100-MIN(100,CASE_INPUT!J17*1.5))) -> 100 | J16: v0.1 heuristics; replace with calibrated models
